<?xml version="1.0" ?>
<!-- =================================================================================== -->
<!-- |    This document was autogenerated by xacro from car_chassis_2diff.xacro        | -->
<!-- |    EDITING THIS FILE BY HAND IS NOT RECOMMENDED                                 | -->
<!-- =================================================================================== -->
<robot name="car_chassis_2diff">
  <material name="blue">
    <color rgba="0.5 0.5 1 0.8"/>
  </material>
  <material name="white">
    <color rgba="0.6 0.6 0.6 1"/>
  </material>
  <!-- <link name="base_footprint">

    </link>
    <gazebo reference="base_footprint">
        <turnGravityOff>false</turnGravityOff>
    </gazebo>

    <joint name="base_footprint_joint" tyoe="fixed">
        <origin xyz="0 0 ${wheel_radius-wheel_joint_z-motor_joint_z}" rpy="0 0 0"  />
        <parent link="base_footprint" />
        <child link="base_link" />
    </joint> -->
  <link name="base_link">
    <visual>
      <origin rpy="0 0 0" xyz="0 0 0"/>
      <geometry>
        <cylinder length="0.08" radius="0.17"/>
      </geometry>
      <material name="yellow">
        <color rgba="0.9 0.9 0.1 0.5"/>
      </material>
    </visual>
  </link>
  <joint name="lf_wheel_joint" type="continuous">
    <origin rpy="0 0 0" xyz="0.0 0.025 0.0"/>
    <parent link="lf_motor"/>
    <child link="lf_wheel_link"/>
    <axis xyz="0 1 0"/>
  </joint>
  <link name="lf_wheel_link">
    <visual>
      <origin rpy="1.570796326795 0 0" xyz="0 0 0"/>
      <geometry>
        <cylinder length="0.015" radius="0.03"/>
      </geometry>
      <material name="white"/>
    </visual>
    <!-- <collision>

            </collision> -->
  </link>
  <joint name="base_lf_motor_joint" type="fixed">
    <origin rpy="0 0 0" xyz="-0.03 0.1 -0.02"/>
    <parent link="base_link"/>
    <child link="lf_motor"/>
  </joint>
  <link name="lf_motor">
    <visual>
      <origin rpy="1.570796326795 0 0" xyz="0 0 0"/>
      <geometry>
        <cylinder length="0.05" radius="0.01"/>
      </geometry>
      <material name="black"/>
    </visual>
  </link>
  <joint name="rt_wheel_joint" type="continuous">
    <origin rpy="0 0 0" xyz="0.0 -0.025 0.0"/>
    <parent link="rt_motor"/>
    <child link="rt_wheel_link"/>
    <axis xyz="0 1 0"/>
  </joint>
  <link name="rt_wheel_link">
    <visual>
      <origin rpy="-1.570796326795 0 0" xyz="0 0 0"/>
      <geometry>
        <cylinder length="0.015" radius="0.03"/>
      </geometry>
      <material name="white"/>
    </visual>
    <!-- <collision>

            </collision> -->
  </link>
  <joint name="base_rt_motor_joint" type="fixed">
    <origin rpy="0 0 0" xyz="-0.03 -0.1 -0.02"/>
    <parent link="base_link"/>
    <child link="rt_motor"/>
  </joint>
  <link name="rt_motor">
    <visual>
      <origin rpy="-1.570796326795 0 0" xyz="0 0 0"/>
      <geometry>
        <cylinder length="0.05" radius="0.01"/>
      </geometry>
      <material name="black"/>
    </visual>
  </link>
  <joint name="base_caster_joint" type="fixed">
    <origin rpy="0 0 0" xyz="0.1 0 -0.04"/>
    <parent link="base_link"/>
    <child link="caster_link"/>
  </joint>
  <link name="caster_link">
    <visual>
      <origin rpy="0 0 0" xyz="0 0 0"/>
      <geometry>
        <sphere radius="0.01"/>
      </geometry>
      <material name="black">
        <color rgba="0.1 0.1 0.1 1"/>
      </material>
    </visual>
  </link>
  <!-- <gazebo>
        <plugin name="differential_drive_controller" filename="libgazebo_ros_diff_drive.so">

        </plugin>
    </gazebo> -->
</robot>

